Workbook

Sheet 요구사항 목록
A1: 책 평가 및 취향 공유 커뮤니티 · 요구사항정의서
A2: 작성 기준일: 2026-08-24 | 개발 환경: Java · Oracle · JDBC · HTML · CSS · JavaScript
A4: 요구사항 ID | B4: 대분류 | C4: 중분류 | D4: 기능명 | E4: 요구사항 내용 | F4: 사용자 | G4: 입력값 | H4: 처리 내용 | I4: 출력·결과 | J4: 우선순위 | K4: 담당자 | L4: 완료 기준 | M4: 진행 상태 | N4: 비고 | O4: 1열 | P4: 2열
A5: MEM-001 | B5: 회원 | C5: 회원가입 | D5: 회원가입 | E5: 비회원은 아이디, 비밀번호, 닉네임 등의 필수정보를 입력하여 회원가입할 수 있어야 한다. | F5: 비회원 | G5: 아이디, 비밀번호, 닉네임 | H5: 회원정보를 검증한 뒤 DB에 저장 | I5: 회원가입 완료 및 로그인 화면 이동 | J5: 필수 | K5: 민기 | L5: 가입 가능한 정보로 회원 레코드가 생성된다. | M5: 미착수
A6: MEM-002 | D6: 아이디 중복 확인 | E6: 이미 사용 중인 아이디로 회원가입할 수 없어야 한다. | F6: 비회원 | G6: 아이디 | H6: MEMBER 테이블에서 동일 아이디 조회 | I6: 사용 가능 또는 중복 안내 | J6: 필수 | K6: 민기 | L6: 중복 아이디 입력 시 가입이 차단된다. | M6: 미착수
A7: MEM-003 | D7: 닉네임 중복 확인 | E7: 이미 사용 중인 닉네임을 사용할 수 없어야 한다. | F7: 비회원 | G7: 닉네임 | H7: MEMBER 테이블에서 동일 닉네임 조회 | I7: 사용 가능 또는 중복 안내 | J7: 필수 | K7: 민기 | L7: 중복 닉네임 입력 시 가입이 차단된다. | M7: 미착수
A8: MEM-004 | C8: 로그인 | D8: 로그인 | E8: 등록된 아이디와 비밀번호로 로그인할 수 있어야 한다. | F8: 비회원 | G8: 아이디, 비밀번호 | H8: 회원정보와 입력값 일치 여부 확인 | I8: 성공 시 메인 이동, 실패 시 오류 표시 | J8: 필수 | K8: 민기 | L8: 정상 회원만 로그인할 수 있다. | M8: 미착수
A9: MEM-005 | D9: 로그인 세션 | E9: 로그인 성공 시 회원 식별정보와 권한을 세션에 저장해야 한다. | F9: 회원 | G9: 로그인 회원정보 | H9: 회원번호, 닉네임, 권한을 세션에 저장 | I9: 회원 전용 메뉴 표시 | J9: 필수 | K9: 민기 | L9: 페이지 이동 후에도 로그인 상태가 유지된다. | M9: 미착수
A10: MEM-006 | D10: 로그아웃 | E10: 사용자는 현재 로그인 세션을 삭제하고 로그아웃할 수 있어야 한다. | F10: 회원 | G10: 로그아웃 요청 | H10: 세션 무효화 | I10: 비회원 상태로 메인 이동 | J10: 필수 | K10: 민기 | L10: 로그아웃 후 회원 전용 기능에 접근할 수 없다. | M10: 미착수
A11: MEM-007 | C11: 마이페이지 | D11: 마이페이지 | E11: 회원은 자신의 프로필과 사이트 활동 내역을 확인할 수 있어야 한다. | F11: 회원 | G11: 로그인 회원번호 | H11: 회원별 평점, 게시글, 티어리스트 등 조회 | I11: 개인 활동 목록 표시 | J11: 중요 | K11: 민기 | L11: 다른 회원의 비공개 활동은 표시되지 않는다. | M11: 미착수
A12: MEM-008 | D12: 회원정보 수정 | E12: 회원은 비밀번호와 닉네임 등 수정 가능한 정보를 변경할 수 있어야 한다. | F12: 회원 | G12: 변경 정보 | H12: 중복 및 형식 검증 후 회원정보 수정 | I12: 수정 완료 안내 | J12: 중요 | K12: 민기 | L12: 수정한 정보가 재로그인 후에도 유지된다. | M12: 미착수
A13: MEM-009 | D13: 북마크 | E13: 회원은 관심 있는 책을 북마크하거나 해제할 수 있어야 한다. | F13: 회원 | G13: 책 번호 | H13: 회원과 책의 북마크 관계를 등록 또는 삭제 | I13: 북마크 상태와 개수 표시 | J13: 선택 | K13: 민기 | L13: 동일 회원과 책의 중복 북마크가 생성되지 않는다. | M13: 미착수
A14: BOOK-001 | B14: 책 | C14: 책 검색 | D14: 책 목록 조회 | E14: 사용자는 관리자가 승인한 책의 목록을 조회할 수 있어야 한다. | F14: 전체 | G14: 목록 요청 | H14: BOOK 상태가 APPROVED인 책만 조회 | I14: 책 목록 표시 | J14: 필수 | K14: 정현 | L14: 승인 대기 또는 거절된 책은 일반 목록에 나오지 않는다. | M14: 미착수
A15: BOOK-002 | D15: 책 상세조회 | E15: 사용자는 책의 제목, 표지, 작가, 장르, 소개와 평점 정보를 확인할 수 있어야 한다. | F15: 전체 | G15: 책 번호 | H15: 책 및 작가·평점 데이터 조회 | I15: 책 상세정보 표시 | J15: 필수 | K15: 정현 | L15: 존재하는 승인 책의 상세정보가 정상 표시된다. | M15: 미착수
A16: BOOK-003 | D16: 책 검색 | E16: 사용자는 책 제목 또는 작가명으로 책을 검색할 수 있어야 한다. | F16: 전체 | G16: 검색어 | H16: 제목 및 작가명 부분일치 검색 | I16: 검색 결과 목록 표시 | J16: 필수 | K16: 정현 | L16: 검색어와 일치하는 승인 책만 표시된다. | M16: 미착수
A17: BOOK-006 | C17: 책 확인 | D17: 책 등록 요청 | E17: 회원 또는 작가 회원은 새로운 책의 등록을 요청할 수 있어야 한다. | F17: 회원·작가 | G17: 책 제목, ISBN, 작가, 출판사, 장르 등 | H17: 중복 확인 후 PENDING 상태로 저장 | I17: 등록 요청 완료 안내 | J17: 중요 | K17: 정현 | L17: 요청한 책이 승인 대기 목록에 생성된다. | M17: 미착수
A18: BOOK-007 | D18: 승인 책 공개 | E18: 시스템은 APPROVED 상태의 책만 일반 사용자에게 공개해야 한다. | F18: 시스템 | G18: BOOK.status | H18: 상태값에 따라 공개 여부 결정 | I18: 승인 책만 목록·검색에 노출 | J18: 필수 | K18: 정현·려립 | L18: PENDING과 REJECTED 책은 일반 조회에서 제외된다. | M18: 미착수
A19: BOOK-008 | D19: 중복 책 확인 | E19: ISBN이 동일한 책이 이미 존재하거나 승인 대기 중이면 중복 등록을 차단해야 한다. | F19: 회원·관리자 | G19: ISBN | H19: 기존 BOOK 데이터와 ISBN 비교 | I19: 중복 안내 또는 등록 진행 | J19: 중요 | K19: 정현·려립 | L19: 동일 ISBN으로 두 건이 등록되지 않는다. | M19: 미착수
A20: RATE-001 | B20: 평점·랭킹 | C20: 평점 관리 | D20: 평점 등록 | E20: 로그인한 회원은 책에 1점부터 5점까지 평점을 등록할 수 있어야 한다. | F20: 회원 | G20: 책 번호, 점수, 한줄평 | H20: 점수 범위와 중복 여부 확인 후 저장 | I20: 평점 등록 및 평균 갱신 | J20: 필수 | K20: 정현 | L20: 유효한 점수와 한줄평이 저장된다. | M20: 미착수
A21: RATE-002 | D21: 중복 평점 방지 | E21: 한 회원은 한 책에 하나의 평점만 보유할 수 있어야 한다. | F21: 회원 | G21: 회원 번호, 책 번호 | H21: 기존 평점 존재 여부 확인 | I21: 신규 등록 차단 또는 수정 안내 | J21: 필수 | K21: 정현 | L21: 회원·책 조합이 중복 저장되지 않는다. | M21: 미착수
A22: RATE-003 | D22: 평점 수정 | E22: 회원은 자신이 등록한 평점과 한줄평을 수정할 수 있어야 한다. | F22: 회원 | G22: 수정 점수, 한줄평 | H22: 작성자 확인 후 데이터 수정 | I22: 수정 내용 및 평균 갱신 | J22: 필수 | K22: 정현 | L22: 작성자 본인의 평가만 수정된다. | M22: 미착수
A23: RATE-004 | D23: 평점 삭제 | E23: 회원은 자신이 등록한 평점을 삭제할 수 있어야 한다. | F23: 회원 | G23: 평점 번호 | H23: 작성자 확인 후 평가 삭제 | I23: 평가 삭제 및 평균 갱신 | J23: 필수 | K23: 정현 | L23: 삭제 후 평가와 집계값이 함께 반영된다. | M23: 미착수
A24: RATE-005 | D24: 평균 평점 | E24: 시스템은 책별 평균 평점과 평가 참여 인원을 계산해야 한다. | F24: 전체 | G24: 책별 평가 데이터 | H24: AVG와 COUNT로 집계 | I24: 평균 평점과 참여 인원 표시 | J24: 필수 | K24: 정현 | L24: 평가 등록·수정·삭제 후 집계가 정확하다. | M24: 미착수
A25: RATE-006 | D25: 평점 분포 | E25: 책 상세페이지에서 1~5점별 평가 인원을 표시할 수 있어야 한다. | F25: 전체 | G25: 책 번호 | H25: 점수별 평가 수 GROUP BY 집계 | I25: 점수별 인원 및 막대 표시 | J25: 선택 | K25: 정현 | L25: 점수별 인원 합계가 전체 참여 인원과 같다. | M25: 미착수
A26: RATE-007 | C26: 랭킹 | D26: 장르별 랭킹 | E26: 사용자는 장르별 평균 평점순 또는 참여 인원순 랭킹을 조회할 수 있어야 한다. | F26: 전체 | G26: 장르, 정렬 기준 | H26: 최소 평가 인원을 적용해 순위 계산 | I26: 장르별 순위 표시 | J26: 중요 | K26: 정현 | L26: 동률 처리 기준에 따라 순서가 일관된다. | M26: 미착수
A27: TIER-001 | B27: 티어리스트 | C27: 티어리스트 관리 | D27: 티어리스트 생성 | E27: 회원은 자신만의 책 티어리스트를 생성할 수 있어야 한다. | F27: 회원 | G27: 제목, 설명, 공개 여부 | H27: TIER_LIST 저장 | I27: 새 티어리스트 표시 | J27: 선택 | K27: 정현 | L27: 로그인 회원 소유의 목록이 생성된다. | M27: 미착수
A28: TIER-002 | D28: 티어 등급 변경 | E28: 회원은 티어리스트에 포함된 책의 등급을 변경할 수 있어야 한다. | F28: 회원 | G28: 항목 번호, 변경 등급 | H28: 소유자 확인 후 등급 수정 | I28: 변경된 위치 표시 | J28: 선택 | K28: 정현 | L28: 본인 티어리스트의 책만 변경할 수 있다. | M28: 미착수
A29: TIER-003 | D29: 책 추가 및 등급 설정 | E29: 회원은 책을 티어리스트에 추가하고 S·A·B·C·D 등급을 지정할 수 있어야 한다. | F29: 회원 | G29: 티어리스트, 책, 등급 | H29: TIER_ITEM 저장 | I29: 등급별 책 표시 | J29: 선택 | K29: 정현 | L29: 허용된 등급만 저장된다. | M29: 미착수
A30: TIER-004 | D30: 책 제외 | E30: 회원은 자신의 티어리스트에서 책을 제외할 수 있어야 한다. | F30: 회원 | G30: 티어 항목 번호 | H30: 소유자 확인 후 TIER_ITEM 삭제 | I30: 목록에서 책 제거 | J30: 선택 | K30: 정현 | L30: 다른 회원의 항목은 삭제되지 않는다. | M30: 미착수
A31: TIER-005 | D31: 공개 설정 | E31: 회원은 티어리스트를 공개 또는 비공개로 설정할 수 있어야 한다. | F31: 회원 | G31: 공개 여부 | H31: TIER_LIST 공개값 수정 | I31: 공개 범위 반영 | J31: 선택 | K31: 정현 | L31: 비공개 목록은 소유자만 조회할 수 있다. | M31: 미착수
A32: IDEAL-001 | B32: 책 이상형 | C32: 책 이상형 진행 | D32: 후보 책 조회 | E32: 회원은 선택한 장르에서 이상형 월드컵 후보를 조회할 수 있어야 한다. | F32: 회원 | G32: 장르 | H32: 승인 책 중 후보 무작위 또는 기준 조회 | I32: 8권의 후보 표시 | J32: 선택 | K32: 정현 | L32: 후보가 부족하면 진행 불가 안내를 표시한다. | M32: 미착수
A33: IDEAL-002 | D33: 8강 진행 | E33: 시스템은 8권의 후보로 대진을 만들고 선택된 책을 다음 라운드로 진출시켜야 한다. | F33: 회원 | G33: 두 책 중 선택 | H33: 라운드별 승자 저장 | I33: 다음 대진 또는 결승 표시 | J33: 선택 | K33: 정현 | L33: 8강부터 결승까지 선택 흐름이 이어진다. | M33: 미착수
A34: IDEAL-003 | C34: 책 이상형 결과 관리 | D34: 결과 저장 | E34: 시스템은 최종 우승 책과 회원의 선택 결과를 저장해야 한다. | F34: 회원 | G34: 최종 우승 책 | H34: IDEAL_RESULT 저장 | I34: 최종 결과 화면 표시 | J34: 선택 | K34: 정현 | L34: 완료한 게임의 우승 결과가 1건 저장된다. | M34: 미착수
A35: IDEAL-004 | D35: 결과 랭킹 | E35: 사용자는 이상형 월드컵 우승 횟수가 높은 책 순위를 조회할 수 있어야 한다. | F35: 전체 | G35: 이상형 결과 데이터 | H35: 책별 우승 횟수 집계 | I35: 이상형 결과 랭킹 표시 | J35: 선택 | K35: 정현 | L35: 우승 횟수와 순위가 집계 데이터와 일치한다. | M35: 미착수
A36: POST-001 | B36: 게시판 | C36: 게시글 필터 | D36: 게시글 목록 | E36: 사용자는 공개된 게시글 목록을 조회할 수 있어야 한다. | F36: 전체 | G36: 목록·카테고리 요청 | H36: 삭제되지 않은 게시글 조회 | I36: 게시글 목록 표시 | J36: 필수 | K36: 려립 | L36: 제목, 작성자, 작성일, 조회수가 표시된다. | M36: 미착수
A37: POST-002 | D37: 게시글 검색 | E37: 사용자는 제목, 내용 또는 작성자 기준으로 게시글을 검색할 수 있어야 한다. | F37: 전체 | G37: 검색 유형, 검색어 | H37: 조건별 부분일치 검색 | I37: 검색 결과 목록 표시 | J37: 중요 | K37: 려립 | L37: 검색 조건과 일치하는 게시글만 표시된다. | M37: 미착수
A38: POST-003 | D38: 게시판 페이징 | E38: 게시글 목록은 지정된 개수 단위로 나누어 표시되어야 한다. | F38: 전체 | G38: 페이지 번호 | H38: 전체 건수와 페이지 범위 계산 | I38: 이전·페이지·다음 표시 | J38: 중요 | K38: 려립 | L38: 첫·마지막 페이지에서 잘못된 이동이 발생하지 않는다. | M38: 미착수
A39: POST-004 | C39: 게시글 | D39: 게시글 등록 | E39: 로그인한 회원은 카테고리, 제목과 내용을 입력하여 게시글을 작성할 수 있어야 한다. | F39: 회원 | G39: 카테고리, 제목, 내용, 스포일러 여부 | H39: 필수값 검증 후 POST 저장 | I39: 작성한 게시글 상세 이동 | J39: 필수 | K39: 려립 | L39: 로그인 회원의 작성자 정보와 함께 저장된다. | M39: 미착수
A40: POST-005 | D40: 게시글 수정 | E40: 작성자는 자신이 작성한 게시글만 수정할 수 있어야 한다. | F40: 회원 | G40: 변경 제목·내용 | H40: 작성자 또는 관리자 권한 확인 후 수정 | I40: 수정된 게시글 표시 | J40: 필수 | K40: 려립 | L40: 권한 없는 회원의 수정 요청은 차단된다. | M40: 미착수
A41: POST-006 | D41: 게시글 삭제 | E41: 작성자는 자신의 게시글을 삭제할 수 있고 관리자는 모든 게시글을 관리할 수 있어야 한다. | F41: 회원·관리자 | G41: 게시글 번호 | H41: 권한 확인 후 삭제 또는 상태 변경 | I41: 목록에서 제거 또는 삭제 안내 | J41: 필수 | K41: 려립 | L41: 작성자와 관리자 외 삭제가 차단된다. | M41: 미착수
...

Sheet 진행 현황
A1: 요구사항 개발 진행 현황
A2: '요구사항 목록' 시트의 우선순위·담당자·진행 상태를 변경하면 아래 집계가 자동으로 갱신됩니다.
A4: 전체 요구사항 | B4: =COUNTA('요구사항 목록'!$A$5:$A$55) -> 51 | D4: 담당자 | E4: 전체 | F4: 필수 | G4: 완료 | H4: 완료율
A5: 필수 요구사항 | B5: =COUNTIF('요구사항 목록'!$J$5:$J$55,"필수") -> 24 | D5: 민기 | E5: =COUNTIF('요구사항 목록'!$K$5:$K$55,D5) -> 9 | F5: =COUNTIFS('요구사항 목록'!$K$5:$K$55,D5,'요구사항 목록'!$J$5:$J$55,"필수") -> 6 | G5: =COUNTIFS('요구사항 목록'!$K$5:$K$55,D5,'요구사항 목록'!$M$5:$M$55,"완료") -> 0 | H5: =IF(E5=0,0,G5/E5) -> 0
A6: 완료 | B6: =COUNTIF('요구사항 목록'!$M$5:$M$55,"완료") -> 0 | D6: 정현 | E6: =COUNTIF('요구사항 목록'!$K$5:$K$55,D6) -> 20 | F6: =COUNTIFS('요구사항 목록'!$K$5:$K$55,D6,'요구사항 목록'!$J$5:$J$55,"필수") -> 8 | G6: =COUNTIFS('요구사항 목록'!$K$5:$K$55,D6,'요구사항 목록'!$M$5:$M$55,"완료") -> 0 | H6: =IF(E6=0,0,G6/E6) -> 0
A7: 진행 중 | B7: =COUNTIF('요구사항 목록'!$M$5:$M$55,"진행 중") -> 0 | D7: 려립 | E7: =COUNTIF('요구사항 목록'!$K$5:$K$55,D7) -> 20 | F7: =COUNTIFS('요구사항 목록'!$K$5:$K$55,D7,'요구사항 목록'!$J$5:$J$55,"필수") -> 9 | G7: =COUNTIFS('요구사항 목록'!$K$5:$K$55,D7,'요구사항 목록'!$M$5:$M$55,"완료") -> 0 | H7: =IF(E7=0,0,G7/E7) -> 0
A8: 완료율 | B8: =IF(B4=0,0,B6/B4) -> 0
D10: 대분류 | E10: 전체 | F10: 필수 | G10: 진행 중 | H10: 완료
D11: 회원 | E11: =COUNTIF('요구사항 목록'!$B$5:$B$55,D11) -> 1 | F11: =COUNTIFS('요구사항 목록'!$B$5:$B$55,D11,'요구사항 목록'!$J$5:$J$55,"필수") -> 1 | G11: =COUNTIFS('요구사항 목록'!$B$5:$B$55,D11,'요구사항 목록'!$M$5:$M$55,"진행 중") -> 0 | H11: =COUNTIFS('요구사항 목록'!$B$5:$B$55,D11,'요구사항 목록'!$M$5:$M$55,"완료") -> 0
D12: 책·작가 | E12: =COUNTIF('요구사항 목록'!$B$5:$B$55,D12) -> 0 | F12: =COUNTIFS('요구사항 목록'!$B$5:$B$55,D12,'요구사항 목록'!$J$5:$J$55,"필수") -> 0 | G12: =COUNTIFS('요구사항 목록'!$B$5:$B$55,D12,'요구사항 목록'!$M$5:$M$55,"진행 중") -> 0 | H12: =COUNTIFS('요구사항 목록'!$B$5:$B$55,D12,'요구사항 목록'!$M$5:$M$55,"완료") -> 0
D13: 평점·랭킹 | E13: =COUNTIF('요구사항 목록'!$B$5:$B$55,D13) -> 1 | F13: =COUNTIFS('요구사항 목록'!$B$5:$B$55,D13,'요구사항 목록'!$J$5:$J$55,"필수") -> 1 | G13: =COUNTIFS('요구사항 목록'!$B$5:$B$55,D13,'요구사항 목록'!$M$5:$M$55,"진행 중") -> 0 | H13: =COUNTIFS('요구사항 목록'!$B$5:$B$55,D13,'요구사항 목록'!$M$5:$M$55,"완료") -> 0
D14: 티어리스트 | E14: =COUNTIF('요구사항 목록'!$B$5:$B$55,D14) -> 1 | F14: =COUNTIFS('요구사항 목록'!$B$5:$B$55,D14,'요구사항 목록'!$J$5:$J$55,"필수") -> 0 | G14: =COUNTIFS('요구사항 목록'!$B$5:$B$55,D14,'요구사항 목록'!$M$5:$M$55,"진행 중") -> 0 | H14: =COUNTIFS('요구사항 목록'!$B$5:$B$55,D14,'요구사항 목록'!$M$5:$M$55,"완료") -> 0
D15: 책 이상형 | E15: =COUNTIF('요구사항 목록'!$B$5:$B$55,D15) -> 1 | F15: =COUNTIFS('요구사항 목록'!$B$5:$B$55,D15,'요구사항 목록'!$J$5:$J$55,"필수") -> 0 | G15: =COUNTIFS('요구사항 목록'!$B$5:$B$55,D15,'요구사항 목록'!$M$5:$M$55,"진행 중") -> 0 | H15: =COUNTIFS('요구사항 목록'!$B$5:$B$55,D15,'요구사항 목록'!$M$5:$M$55,"완료") -> 0
D16: 게시판 | E16: =COUNTIF('요구사항 목록'!$B$5:$B$55,D16) -> 1 | F16: =COUNTIFS('요구사항 목록'!$B$5:$B$55,D16,'요구사항 목록'!$J$5:$J$55,"필수") -> 1 | G16: =COUNTIFS('요구사항 목록'!$B$5:$B$55,D16,'요구사항 목록'!$M$5:$M$55,"진행 중") -> 0 | H16: =COUNTIFS('요구사항 목록'!$B$5:$B$55,D16,'요구사항 목록'!$M$5:$M$55,"완료") -> 0
D17: 댓글 | E17: =COUNTIF('요구사항 목록'!$B$5:$B$55,D17) -> 1 | F17: =COUNTIFS('요구사항 목록'!$B$5:$B$55,D17,'요구사항 목록'!$J$5:$J$55,"필수") -> 0 | G17: =COUNTIFS('요구사항 목록'!$B$5:$B$55,D17,'요구사항 목록'!$M$5:$M$55,"진행 중") -> 0 | H17: =COUNTIFS('요구사항 목록'!$B$5:$B$55,D17,'요구사항 목록'!$M$5:$M$55,"완료") -> 0
D18: 관리자 | E18: =COUNTIF('요구사항 목록'!$B$5:$B$55,D18) -> 1 | F18: =COUNTIFS('요구사항 목록'!$B$5:$B$55,D18,'요구사항 목록'!$J$5:$J$55,"필수") -> 1 | G18: =COUNTIFS('요구사항 목록'!$B$5:$B$55,D18,'요구사항 목록'!$M$5:$M$55,"진행 중") -> 0 | H18: =COUNTIFS('요구사항 목록'!$B$5:$B$55,D18,'요구사항 목록'!$M$5:$M$55,"완료") -> 0

Sheet 업무 규칙
A1: 업무 규칙
A3: 규칙 ID | B3: 영역 | C3: 규칙 내용 | D3: 구현 기준 | E3: 우선순위
A4: BR-001 | B4: 평점 | C4: 회원은 하나의 책에 하나의 평점만 등록할 수 있다. | D4: RATING에 UNIQUE(member_id, book_id) 적용 | E4: 필수
A5: BR-002 | B5: 평점 | C5: 평점은 1점부터 5점까지만 등록할 수 있다. | D5: CHECK(score BETWEEN 1 AND 5) | E5: 필수
A6: BR-003 | B6: 책 | C6: 승인 상태가 APPROVED인 책만 일반 목록·검색·랭킹에 표시한다. | D6: BOOK.status 조건 적용 | E6: 필수
A7: BR-004 | B7: 게시판 | C7: 게시글 작성자와 관리자만 게시글을 수정·삭제할 수 있다. | D7: 세션 member_id 및 role 확인 | E7: 필수
A8: BR-005 | B8: 권한 | C8: 일반 회원은 관리자 페이지에 접근할 수 없다. | D8: 세션 role=ADMIN 확인 | E8: 필수
A9: BR-006 | B9: 좋아요 | C9: 동일 회원은 동일 게시글에 한 번만 좋아요를 등록할 수 있다. | D9: UNIQUE(post_id, member_id) | E9: 선택
A10: BR-007 | B10: 티어리스트 | C10: 비공개 티어리스트는 작성자만 조회할 수 있다. | D10: 공개 여부와 소유자 확인 | E10: 선택
A11: BR-008 | B11: 책 승인 | C11: 책 등록 거절 시 관리자는 거절 사유를 입력해야 한다. | D11: 거절 처리 전 필수값 검증 | E11: 필수
A12: BR-009 | B12: 회원 | C12: 정지·탈퇴·영구제한 회원은 새 콘텐츠를 작성할 수 없다. | D12: MEMBER.status 확인 | E12: 중요
A13: BR-010 | B13: 게시판 | C13: 게시글 상세페이지 조회 시 조회수를 증가시킨다. | D13: 상세조회 트랜잭션에서 증가 | E13: 중요
A14: BR-011 | B14: 책 | C14: 동일 ISBN의 책은 중복 등록할 수 없다. | D14: ISBN UNIQUE 또는 중복조회 | E14: 중요
A15: BR-012 | B15: 삭제 | C15: 연결 데이터가 있는 콘텐츠는 가능한 경우 상태값을 이용해 소프트 삭제한다. | D15: ACTIVE/DELETED 상태 사용 | E15: 중요

Sheet 사용자 권한
A1: 사용자 유형별 권한
A3: 사용자 유형 | B3: 책·랭킹 조회 | C3: 평점·북마크 | D3: 게시글·댓글 | E3: 티어·이상형 | F3: 책 등록 요청 | G3: 관리자 기능 | H3: 권한 설명
A4: 비회원 | B4: 가능 | C4: 불가 | D4: 불가 | E4: 불가 | F4: 불가 | G4: 불가 | H4: 공개 책·랭킹·게시글만 조회
A5: 일반 회원 | B5: 가능 | C5: 가능 | D5: 가능 | E5: 가능 | F5: 가능 | G5: 불가 | H5: 자신의 콘텐츠만 수정·삭제
A6: 작가 회원 | B6: 가능 | C6: 가능 | D6: 가능 | E6: 가능 | F6: 가능 | G6: 불가 | H6: 일반 회원 기능과 자신의 책 등록 요청
A7: 관리자 | B7: 가능 | C7: 가능 | D7: 가능 | E7: 가능 | F7: 가능 | G7: 가능 | H7: 전체 콘텐츠와 계정 및 승인 업무 관리

Sheet 개발 범위
A1: 개발 단계 및 담당 범위
A3: 개발 단계 | B3: 우선순위 | C3: 담당자 | D3: 개발 범위 | E3: 목적 | F3: 완료 시점
A4: 1 | B4: 필수 | C4: 민기 | D4: 회원가입·로그인·로그아웃·세션 | E4: 사이트 사용자 식별과 권한 처리 | F4: 최초 시연 가능
A5: 1 | B5: 필수 | C5: 정현 | D5: AUTHOR·BOOK 테이블, 책 목록·상세·검색 | E5: 모든 책 기반 기능의 선행조건 | F5: 최초 시연 가능
A6: 1 | B6: 필수 | C6: 려립 | D6: POST 테이블, 게시판 CRUD | E6: 독립 개발 가능한 커뮤니티 핵심 | F6: 최초 시연 가능
A7: 2 | B7: 중요 | C7: 민기 | D7: 마이페이지·회원정보 수정 | E7: 회원별 활동 연결 | F7: 핵심 기능 완료 후
A8: 2 | B8: 중요 | C8: 정현 | D8: 평점 CRUD·평균·장르별 랭킹 | E8: 책 평가 서비스 완성 | F8: 핵심 기능 완료 후
A9: 2 | B9: 필수 | C9: 려립 | D9: 관리자 책 승인·거절 | E9: 승인된 책만 공개 | F9: 핵심 기능 완료 후
A10: 3 | B10: 중요 | C10: 려립 | D10: 게시판 검색·필터·페이징·댓글 | E10: 커뮤니티 사용성 강화 | F10: 여유 시 구현
A11: 3 | B11: 선택 | C11: 민기 | D11: 북마크·독서 개인화 | E11: 마이페이지 활용 확대 | F11: 여유 시 구현
A12: 3 | B12: 선택 | C12: 정현 | D12: 티어리스트·평점 분포 | E12: 사이트 차별화 | F12: 여유 시 구현
A13: 4 | B13: 선택 | C13: 정현 | D13: 책 이상형 월드컵 | E13: 대표 차별화 콘텐츠 | F13: 확장 기능
A14: 4 | B14: 선택 | C14: 민기 | D14: 취향 일치율 | E14: 회원 데이터 활용 | F14: 확장 기능
A15: 4 | B15: 선택 | C15: 려립 | D15: 좋아요·스포일러·대시보드·관리 로그 | E15: 운영과 참여 기능 강화 | F15: 확장 기능

Sheet 코드 정의
A1: 상태·권한·분류 코드 정의
A3: 필드 | B3: 코드값 | C3: 설명
A4: MEMBER.role | B4: USER | C4: 일반 회원
A5: MEMBER.role | B5: AUTHOR | C5: 작가 회원
A6: MEMBER.role | B6: ADMIN | C6: 관리자
A7: MEMBER.status | B7: ACTIVE | C7: 정상
A8: MEMBER.status | B8: SUSPENDED | C8: 활동 정지
A9: MEMBER.status | B9: WITHDRAWN | C9: 탈퇴
A10: MEMBER.status | B10: BANNED | C10: 영구 제한
A11: BOOK.status | B11: PENDING | C11: 승인 대기
A12: BOOK.status | B12: APPROVED | C12: 승인 완료·일반 공개
A13: BOOK.status | B13: REJECTED | C13: 승인 거절
A14: TIER.grade | B14: S | C14: 최상위
... A24: POST.category | B24: NOTICE | C24: 공지사항
